<?xml version="1.0" ?>
<robot name="new_finger" xmlns:xacro="http://www.ros.org/wiki/xacro">

<xacro:include filename="$(find new_finger_description)/urdf/materials.xacro" />
<xacro:include filename="$(find new_finger_description)/urdf/new_finger.trans" />
<xacro:include filename="$(find new_finger_description)/urdf/new_finger.gazebo" />
<link name="base_link">
  <inertial>
    <origin rpy="0 0 0" xyz="-3.172582489701302e-14 0.0012359787607253243 -0.025536609468604348"/>
    <mass value="0.011430485562037091"/>
    <inertia ixx="2e-06" ixy="0.0" ixz="-0.0" iyy="3e-06" iyz="0.0" izz="0.0"/>
  </inertial>
  <visual>
    <origin rpy="0 0 0" xyz="0 0 0"/>
    <geometry>
      <mesh filename="package://new_finger_description/meshes/base_link.stl" scale="0.001 0.001 0.001"/>
    </geometry>
    <material name="steel_satin"/>
  </visual>
  <collision>
    <origin rpy="0 0 0" xyz="0 0 0"/>
    <geometry>
      <mesh filename="package://new_finger_description/meshes/base_link.stl" scale="0.001 0.001 0.001"/>
    </geometry>
  </collision>
</link>

<link name="mcp_pitch_link_v1_1">
  <inertial>
    <origin rpy="0 0 0" xyz="-3.3123220041354627e-15 0.008094259781153353 -0.023280808426458743"/>
    <mass value="0.03649234719314178"/>
    <inertia ixx="7e-06" ixy="-0.0" ixz="0.0" iyy="7e-06" iyz="-0.0" izz="3e-06"/>
  </inertial>
  <visual>
    <origin rpy="0 0 0" xyz="-0.0 -0.002 0.043"/>
    <geometry>
      <mesh filename="package://new_finger_description/meshes/mcp_pitch_link_v1_1.stl" scale="0.001 0.001 0.001"/>
    </geometry>
    <material name="steel_satin"/>
  </visual>
  <collision>
    <origin rpy="0 0 0" xyz="-0.0 -0.002 0.043"/>
    <geometry>
      <mesh filename="package://new_finger_description/meshes/mcp_pitch_link_v1_1.stl" scale="0.001 0.001 0.001"/>
    </geometry>
  </collision>
</link>

<link name="connector_1_v1_1">
  <inertial>
    <origin rpy="0 0 0" xyz="0.000249999999999998 0.0 -0.0074999999701438474"/>
    <mass value="0.00374307805216622"/>
    <inertia ixx="0.0" ixy="0.0" ixz="-0.0" iyy="0.0" iyz="-0.0" izz="0.0"/>
  </inertial>
  <visual>
    <origin rpy="0 0 0" xyz="0.0 -0.0095 0.084"/>
    <geometry>
      <mesh filename="package://new_finger_description/meshes/connector_1_v1_1.stl" scale="0.001 0.001 0.001"/>
    </geometry>
    <material name="steel_satin"/>
  </visual>
  <collision>
    <origin rpy="0 0 0" xyz="0.0 -0.0095 0.084"/>
    <geometry>
      <mesh filename="package://new_finger_description/meshes/connector_1_v1_1.stl" scale="0.001 0.001 0.001"/>
    </geometry>
  </collision>
</link>

<link name="pip_pitch_link_v1_1">
  <inertial>
    <origin rpy="0 0 0" xyz="-0.0014999999999999935 0.0008416136964378776 -0.016889258448993236"/>
    <mass value="0.039658823128533346"/>
    <inertia ixx="8e-06" ixy="-0.0" ixz="-0.0" iyy="8e-06" iyz="-0.0" izz="3e-06"/>
  </inertial>
  <visual>
    <origin rpy="0 0 0" xyz="-0.0015 -0.0095 0.099"/>
    <geometry>
      <mesh filename="package://new_finger_description/meshes/pip_pitch_link_v1_1.stl" scale="0.001 0.001 0.001"/>
    </geometry>
    <material name="steel_satin"/>
  </visual>
  <collision>
    <origin rpy="0 0 0" xyz="-0.0015 -0.0095 0.099"/>
    <geometry>
      <mesh filename="package://new_finger_description/meshes/pip_pitch_link_v1_1.stl" scale="0.001 0.001 0.001"/>
    </geometry>
  </collision>
</link>

<link name="connector_2_v1_1">
  <inertial>
    <origin rpy="0 0 0" xyz="0.00025000000000000575 -5.204170427930421e-18 -0.007499999970143806"/>
    <mass value="0.00374307805216622"/>
    <inertia ixx="0.0" ixy="-0.0" ixz="0.0" iyy="0.0" iyz="-0.0" izz="0.0"/>
  </inertial>
  <visual>
    <origin rpy="0 0 0" xyz="-0.0 -0.0095 0.135"/>
    <geometry>
      <mesh filename="package://new_finger_description/meshes/connector_2_v1_1.stl" scale="0.001 0.001 0.001"/>
    </geometry>
    <material name="steel_satin"/>
  </visual>
  <collision>
    <origin rpy="0 0 0" xyz="-0.0 -0.0095 0.135"/>
    <geometry>
      <mesh filename="package://new_finger_description/meshes/connector_2_v1_1.stl" scale="0.001 0.001 0.001"/>
    </geometry>
  </collision>
</link>

<link name="dip_link_v1_1">
  <inertial>
    <origin rpy="0 0 0" xyz="-0.0014968692593847616 0.00048340360385456214 -0.00543640255956615"/>
    <mass value="0.018983457271726564"/>
    <inertia ixx="1e-06" ixy="-0.0" ixz="0.0" iyy="1e-06" iyz="-0.0" izz="1e-06"/>
  </inertial>
  <visual>
    <origin rpy="0 0 0" xyz="-0.0015 -0.0095 0.15"/>
    <geometry>
      <mesh filename="package://new_finger_description/meshes/dip_link_v1_1.stl" scale="0.001 0.001 0.001"/>
    </geometry>
    <material name="steel_satin"/>
  </visual>
  <collision>
    <origin rpy="0 0 0" xyz="-0.0015 -0.0095 0.15"/>
    <geometry>
      <mesh filename="package://new_finger_description/meshes/dip_link_v1_1.stl" scale="0.001 0.001 0.001"/>
    </geometry>
  </collision>
</link>

<link name="connector_3_v1_1">
  <inertial>
    <origin rpy="0 0 0" xyz="0.00025000000000004603 -8.673617379884035e-18 -0.007499999970143834"/>
    <mass value="0.00374307805216622"/>
    <inertia ixx="0.0" ixy="-0.0" ixz="-0.0" iyy="0.0" iyz="0.0" izz="0.0"/>
  </inertial>
  <visual>
    <origin rpy="0 0 0" xyz="-0.0 -0.0095 0.161"/>
    <geometry>
      <mesh filename="package://new_finger_description/meshes/connector_3_v1_1.stl" scale="0.001 0.001 0.001"/>
    </geometry>
    <material name="steel_satin"/>
  </visual>
  <collision>
    <origin rpy="0 0 0" xyz="-0.0 -0.0095 0.161"/>
    <geometry>
      <mesh filename="package://new_finger_description/meshes/connector_3_v1_1.stl" scale="0.001 0.001 0.001"/>
    </geometry>
  </collision>
</link>

<link name="tip_link_v1_1">
  <inertial>
    <origin rpy="0 0 0" xyz="-0.0015000228538777308 -0.0006333260004305636 -0.0055000162640794215"/>
    <mass value="0.0165936992661325"/>
    <inertia ixx="1e-06" ixy="0.0" ixz="-0.0" iyy="1e-06" iyz="0.0" izz="1e-06"/>
  </inertial>
  <visual>
    <origin rpy="0 0 0" xyz="-0.0015 -0.0095 0.176"/>
    <geometry>
      <mesh filename="package://new_finger_description/meshes/tip_link_v1_1.stl" scale="0.001 0.001 0.001"/>
    </geometry>
    <material name="steel_satin"/>
  </visual>
  <collision>
    <origin rpy="0 0 0" xyz="-0.0015 -0.0095 0.176"/>
    <geometry>
      <mesh filename="package://new_finger_description/meshes/tip_link_v1_1.stl" scale="0.001 0.001 0.001"/>
    </geometry>
  </collision>
</link>

<joint name="mcp_yaw" type="continuous">
  <origin rpy="0 0 0" xyz="0.0 0.002 -0.043"/>
  <parent link="base_link"/>
  <child link="mcp_pitch_link_v1_1"/>
  <axis xyz="0.0 1.0 0.0"/>
</joint>

<joint name="mcp_pitch" type="continuous">
  <origin rpy="0 0 0" xyz="-0.0 0.0075 -0.041"/>
  <parent link="mcp_pitch_link_v1_1"/>
  <child link="connector_1_v1_1"/>
  <axis xyz="-1.0 0.0 0.0"/>
</joint>

<joint name="Rigid3" type="fixed">
  <origin rpy="0 0 0" xyz="0.0015 0.0 -0.015"/>
  <parent link="connector_1_v1_1"/>
  <child link="pip_pitch_link_v1_1"/>
</joint>

<joint name="pip_pitch" type="continuous">
  <origin rpy="0 0 0" xyz="-0.0015 0.0 -0.036"/>
  <parent link="pip_pitch_link_v1_1"/>
  <child link="connector_2_v1_1"/>
  <axis xyz="-1.0 0.0 -0.0"/>
</joint>

<joint name="Rigid5" type="fixed">
  <origin rpy="0 0 0" xyz="0.0015 0.0 -0.015"/>
  <parent link="connector_2_v1_1"/>
  <child link="dip_link_v1_1"/>
</joint>

<joint name="dip_pitch" type="continuous">
  <origin rpy="0 0 0" xyz="-0.0015 0.0 -0.011"/>
  <parent link="dip_link_v1_1"/>
  <child link="connector_3_v1_1"/>
  <axis xyz="-1.0 0.0 -0.0"/>
</joint>

<joint name="Rigid7" type="fixed">
  <origin rpy="0 0 0" xyz="0.0015 0.0 -0.015"/>
  <parent link="connector_3_v1_1"/>
  <child link="tip_link_v1_1"/>
</joint>

</robot>
